Workbook

Sheet Introduction
A1: Introduction
A2: This worksheet works through quality/credibility/strength of evidence assessments.
A4: Sheet 1 (AMSTAR-2): AMSTAR-2 assessment for each included meta-analysis and systematic review.
A5: Sheet 2 (Credibility assessment): Credibility assessment for each second-order meta-analytic finding.
A6: Sheet 3 (GRADE assessment): GRADE assessment for each second-order meta-analytic finding.
A8: For each finding in Sheet 2 and Sheet 3, we assess sensitivity and specificity separately. We provide a classification of credibility/GRADE based on the lower of the two.
A12: AMSTAR-2:
A13: There are 16 domains (7 critical) for meta-analyses, and 13 domains (5 critical) for systematic reviews.
A19: Credibility of findings:
A20: There are five classes of credibility: I (convincing), II (highly suggestive), III (suggestive), IV (weak), and V (no evidence).
A21: We assess credibility based on four domains: volume of evidence, consistency of evidence, bias/quality of evidence, coherence of evidence.
A22: We assign an overall credibility score for each pooled meta-analytic finding based on the lowest class recorded.
... A1048576: This worksheet includes the AMSTAR-2 assessment for each included meta-analysis and systematic review

Sheet AMSTAR-2
A1: Meta-analysis | B1: Question and inclusion | C1: Protocol | D1: Study Design | E1: Comprehensive search | F1: Study selection | G1: Data extraction | H1: Excluded studies justification | I1: Included study details | J1: Risk of Bias | K1: Funding sources | L1: Statistical methods in meta-analysis | M1: Risk of bias in meta-analysis | N1: Risk of bias in results interpretation | O1: Explanation of heterogeneity | P1: Publication bias | Q1: Conflict of interest | R1: Overall
A2: Beculic 2024 | B2: Yes | C2: Yes | D2: Yes | E2: Partial Yes | F2: No | G2: No | H2: No | I2: Partial Yes | J2: Yes | K2: No | L2: Yes | M2: Yes | N2: No | O2: Yes | P2: Yes | Q2: Yes | R2: Critically low
A3: Binh 2025 | B3: Yes | C3: Yes | D3: Yes | E3: Partial Yes | F3: Yes | G3: Yes | H3: No | I3: Partial Yes | J3: Yes | K3: No | L3: Yes | M3: No | N3: Yes | O3: Yes | P3: Yes | Q3: Yes | R3: Critically low
A4: Dashti 2024 | B4: Yes | C4: Partial Yes | D4: Yes | E4: Partial Yes | F4: Yes | G4: No | H4: No | I4: Partial Yes | J4: Yes | K4: No | L4: Yes | M4: No | N4: No | O4: No | P4: Yes | Q4: Yes | R4: Critically low
A5: Den Hengst 2025 | B5: Yes | C5: Partial Yes | D5: Yes | E5: Partial Yes | F5: Yes | G5: No | H5: No | I5: Partial Yes | J5: Yes | K5: No | L5: Yes | M5: No | N5: No | O5: Yes | P5: Partial Yes | Q5: Yes | R5: Critically low
A6: Hansen 2024 | B6: Yes | C6: Yes | D6: Yes | E6: Partial Yes | F6: Yes | G6: Yes | H6: No | I6: Yes | J6: Yes | K6: No | L6: Yes | M6: No | N6: Yes | O6: Yes | P6: No | Q6: Yes | R6: Critically low
A7: Husarek 2024 | B7: Yes | C7: No | D7: No | E7: Partial Yes | F7: Yes | G7: No | H7: No | I7: Yes | J7: Yes | K7: Yes | L7: Yes | M7: Yes | N7: Yes | O7: Yes | P7: No | Q7: Yes | R7: Critically low
A8: Ju 2025 | B8: Yes | C8: Partial Yes | D8: Yes | E8: Partial Yes | F8: Yes | G8: Yes | H8: No | I8: Yes | J8: Yes | K8: No | L8: Yes | M8: No | N8: Yes | O8: Yes | P8: Yes | Q8: Yes | R8: Low
A9: Jung 2024 | B9: No | C9: Yes | D9: No | E9: Partial Yes | F9: Yes | G9: Yes | H9: No | I9: Yes | J9: Yes | K9: No | L9: Yes | M9: Yes | N9: Yes | O9: No | P9: Yes | Q9: Yes | R9: Low
A10: Kraus 2023 | B10: Yes | C10: Partial Yes | D10: No | E10: No | F10: No | G10: No | H10: No | I10: Yes | J10: Yes | K10: No | L10: Yes | M10: No | N10: Yes | O10: Yes | P10: No | Q10: Yes | R10: Critically low
A11: Kuo 2022 | B11: Yes | C11: Yes | D11: Yes | E11: Yes | F11: Yes | G11: Yes | H11: No | I11: Yes | J11: Yes | K11: No | L11: Yes | M11: Yes | N11: Yes | O11: Yes | P11: Yes | Q11: Yes | R11: Low
A12: Li 2024 | B12: Yes | C12: Yes | D12: Yes | E12: Partial Yes | F12: Yes | G12: Yes | H12: No | I12: Yes | J12: Yes | K12: No | L12: Yes | M12: No | N12: Yes | O12: Yes | P12: Yes | Q12: Yes | R12: Low
... A22: Zhang 2022 | B22: Yes | C22: Yes | D22: Yes | E22: Partial Yes | F22: No | G22: Yes | H22: No | I22: Yes | J22: Yes | K22: No | L22: Yes | M22: Yes | N22: Yes | O22: Yes | P22: Yes | Q22: Yes | R22: Low
A24: Meta-analyses not included in second-order meta-analysis
A25: Lex 2023 | B25: Yes | C25: Partial Yes | D25: Yes | E25: Partial Yes | F25: Yes | G25: Yes | H25: No | I25: Yes | J25: No | K25: No | L25: Yes | M25: No | N25: No | O25: No | P25: No | Q25: Yes | R25: Critically low
A26: Namireddy 2024 | B26: Yes | C26: Partial Yes | D26: Yes | E26: Yes | F26: Yes | G26: Yes | H26: No | I26: Parital Yes | J26: Yes | K26: No | L26: Yes | M26: Yes | N26: Yes | O26: Yes | P26: No | Q26: Yes | R26: Critically low
A27: Raj 2024 | B27: Yes | C27: Yes | D27: Yes | E27: Yes | F27: Yes | G27: No | H27: No | I27: Yes | J27: Yes | K27: No | L27: No | M27: No | N27: Yes | O27: No | P27: No | Q27: Yes | R27: Critically low
A28: Wang 2025 | B28: Yes | C28: No | D28: Yes | E28: Partial Yes | F28: Yes | G28: Yes | H28: No | I28: Parital Yes | J28: No | K28: No | L28: Yes | M28: No | N28: No | O28: No | P28: Yes | Q28: Yes | R28: Critically low
A30: Systematic review | B30: Question and inclusion | C30: Protocol | D30: Study Design | E30: Comprehensive search | F30: Study selection | G30: Data extraction | H30: Excluded studies justification | I30: Included study details | J30: Risk of Bias | K30: Funding sources | L30: Risk of bias in results interpretation | M30: Explanation of heterogeneity | N30: Conflict of interest | O30: Overall
A31: Ashworth (2025) | B31: Yes | C31: Yes | D31: Yes | E31: Yes | F31: Yes | G31: Yes | H31: No | I31: Yes | J31: Yes | K31: No | L31: Yes | M31: No | N31: Yes | O31: Low
A32: Collins (2025) | B32: Yes | C32: No | D32: No | E32: Partial Yes | F32: No | G32: Yes | H32: No | I32: Partial Yes | J32: No | K32: No | L32: No | M32: Yes | N32: Yes | O32: Critically low
A33: Dankelman (2023) | B33: Yes | C33: No | D33: Yes | E33: Partial Yes | F33: Yes | G33: Yes | H33: No | I33: Partial Yes | J33: Yes | K33: No | L33: No | M33: No | N33: Yes | O33: Critically low
A34: Gatineau (2024) | B34: No | C34: No | D34: No | E34: No | F34: No | G34: No | H34: No | I34: Partial Yes | J34: Partial Yes | K34: No | L34: Yes | M34: Yes | N34: Yes | O34: Critically low
A35: Gupta (2023) | B35: Yes | C35: Partial Yes | D35: Yes | E35: Partial Yes | F35: Yes | G35: No | H35: No | I35: Partial Yes | J35: No | K35: No | L35: No | M35: No | N35: Yes | O35: Critically low
A36: Keller (2023) | B36: No | C36: Partial Yes | D36: Yes | E36: Partial Yes | F36: Yes | G36: No | H36: No | I36: Partial Yes | J36: No | K36: No | L36: No | M36: No | N36: Yes | O36: Critically low
A37: Khatik (2022) | B37: No | C37: No | D37: No | E37: No | F37: No | G37: No | H37: No | I37: Partial Yes | J37: No | K37: No | L37: No | M37: No | N37: No | O37: Critically low
A38: Khatik (2024) | B38: No | C38: No | D38: No | E38: No | F38: No | G38: No | H38: No | I38: Partial Yes | J38: No | K38: No | L38: No | M38: No | N38: Yes | O38: Critically low
A39: Kutbi (2024) | B39: No | C39: Partial Yes | D39: Yes | E39: Partial Yes | F39: No | G39: No | H39: No | I39: Partial Yes | J39: No | K39: No | L39: No | M39: Yes | N39: Yes | O39: Critically low
A40: Kwee (2025) | B40: Yes | C40: No | D40: Yes | E40: Partial Yes | F40: No | G40: No | H40: Yes | I40: Partial Yes | J40: Yes | K40: No | L40: Yes | M40: Yes | N40: Yes | O40: Low
A41: Langerhuizen (2019) | B41: Yes | C41: Yes | D41: Yes | E41: Yes | F41: Yes | G41: Yes | H41: No | I41: Yes | J41: Yes | K41: No | L41: No | M41: No | N41: Yes | O41: Critically low
... A55: Vescio (2024) | B55: No | C55: No | D55: Yes | E55: Partial Yes | F55: No | G55: No | H55: No | I55: No | J55: No | K55: No | L55: No | M55: No | N55: Yes | O55: Critically low

Sheet Credibility assessment
H1: Volume of evidence | K1: Class | L1: Consistency | M1: Class | N1: Bias/quality | P1: Class | Q1: Coherence | R1: Class | S1: Overall
A2: Group | B2: Finding | C2: Point estimate | D2: 95% CI lower | E2: 95% CI upper | F2: 95% PI lower | G2: 95% PI upper | H2: Meta-analyses = n | I2: Number of primary studies | J2: 95% CI width | K2: 1 to 5 | L2: Overlap ratio (% PI covered by CI) | M2: 1 to 5 | N2: % of moderate/high AMSTAR2 | O2: % of publication bias | P2: 1 to 5 | Q2: Narrative synthesis concordant? | R2: 1 to 5 | S2: Credibility
A3: Overall AI performance | B3: Sensitivity | C3: 0.897 | D3: 0.882 | E3: 0.91 | F3: 0.755 | G3: 0.961 | H3: 22 | I3: 254 | J3: =E3-D3 -> 0.028 | K3: 1 | L3: =(E3-D3)/(G3-F3) -> 0.13592233 | M3: 4 | N3: 0 | O3: 50 | P3: 4 | Q3: Y | R3: 1 | S3: IV
B4: Specificity | C4: 0.904 | D4: 0.891 | E4: 0.916 | F4: 0.824 | G4: 0.95 | H4: 20 | I4: 254 | J4: =E4-D4 -> 0.025 | K4: 1 | L4: =(E4-D4)/(G4-F4) -> 0.1984127 | M4: 4 | N4: 0 | O4: 50 | P4: 4 | Q4: Y | R4: 1
A5: Overall clinician performance | B5: Sensitivity | C5: 0.858 | D5: 0.781 | E5: 0.91 | F5: 0.546 | G5: 0.968 | H5: 7 | I5: 53 | J5: =E5-D5 -> 0.129 | K5: 2 | L5: =(E5-D5)/(G5-F5) -> 0.3056872 | M5: 2 | N5: 0 | O5: 33 | P5: 3 | Q5: Y | R5: 1 | S5: III
B6: Specificity | C6: 0.932 | D6: 0.92 | E6: 0.943 | F6: 0.909 | G6: 0.95 | H6: 6 | I6: 53 | J6: =E6-D6 -> 0.023 | K6: 1 | L6: =(E6-D6)/(G6-F6) -> 0.56097561 | M6: 1 | N6: 0 | O6: 33 | P6: 3 | Q6: Y | R6: 1
A7: Overall AI-as-assistant performance | B7: Sensitivity | C7: 0.895 | D7: 0.63 | E7: 0.977 | F7: 0.311 | G7: 0.994 | H7: 4 | I7: 17 | J7: =E7-D7 -> 0.347 | K7: 5 | L7: =(E7-D7)/(G7-F7) -> 0.50805271 | M7: 1 | N7: 0 | O7: 0 | P7: 3 | Q7: Y | R7: 1 | S7: V
B8: Specificity | C8: 0.939 | D8: 0.899 | E8: 0.963 | F8: 0.851 | G8: 0.976 | H8: 4 | I8: 17 | J8: =E8-D8 -> 0.064 | K8: 4 | L8: =(E8-D8)/(G8-F8) -> 0.512 | M8: 1 | N8: 0 | O8: 0 | P8: 3 | Q8: Y | R8: 1
A10: AI-alone by modality
A11: Radiographs | B11: Sensitivity | C11: 0.903 | D11: 0.878 | E11: 0.925 | F11: 0.719 | G11: 0.972 | H11: 14 | I11: 147 | J11: =E11-D11 -> 0.047 | K11: 1 | L11: =(E11-D11)/(G11-F11) -> 0.18577075 | M11: 4 | N11: 0 | O11: 64 | P11: 4 | Q11: Y | R11: 1 | S11: IV
B12: Specificity | C12: 0.895 | D12: 0.882 | E12: 0.906 | F12: 0.815 | G12: 0.943 | H12: 14 | I12: 147 | J12: =E12-D12 -> 0.024 | K12: 1 | L12: =(E12-D12)/(G12-F12) -> 0.1875 | M12: 4 | N12: 0 | O12: 64 | P12: 4 | Q12: Y | R12: 1
A13: CT | B13: Sensitivity | C13: 0.866 | D13: 0.838 | E13: 0.89 | F13: 0.819 | G13: 0.903 | H13: 7 | I13: 84 | J13: =E13-D13 -> 0.052 | K13: 1 | L13: =(E13-D13)/(G13-F13) -> 0.61904762 | M13: 1 | N13: 0 | O13: 57 | P13: 4 | Q13: Y | R13: 1 | S13: IV
B14: Specificity | C14: 0.936 | D14: 0.885 | E14: 0.965 | F14: 0.796 | G14: 0.982 | H14: 5 | I14: 84 | J14: =E14-D14 -> 0.08 | K14: 1 | L14: =(E14-D14)/(G14-F14) -> 0.43010753 | M14: 2 | N14: 0 | O14: 57 | P14: 4 | Q14: Partial Y - lower bounds wider in narrative synthesis | R14: 2
A15: MRI | B15: Sensitivity | C15: 0.91 | D15: 0.83 | E15: 0.95 | F15: N/A | G15: N/A | H15: 1 | I15: 5 | J15: =E15-D15 -> 0.12 | K15: 5 | L15: N/A | M15: 5 | N15: 0 | O15: 100 | P15: 4 | Q15: Y | R15: 1 | S15: V
B16: Specificity | C16: 0.89 | D16: 0.84 | E16: 0.93 | F16: N/A | G16: N/A | H16: 1 | I16: 5 | J16: =E16-D16 -> 0.09 | K16: 5 | L16: N/A | M16: 5 | N16: 0 | O16: 100 | P16: 4 | Q16: Y | R16: 1
A17: DEXA | B17: Sensitivity | C17: 0.84 | D17: 0.8 | E17: 0.88 | F17: N/A | G17: N/A | H17: 1 | I17: 4 | J17: =E17-D17 -> 0.08 | K17: 5 | L17: N/A | M17: 5 | N17: 0 | O17: 0 | P17: 3 | Q17: Y | R17: 1 | S17: V
B18: Specificity | C18: 0.93 | D18: 0.89 | E18: 0.96 | F18: N/A | G18: N/A | H18: 1 | I18: 4 | J18: =E18-D18 -> 0.07 | K18: 5 | L18: N/A | M18: 5 | N18: 0 | O18: 0 | P18: 3 | Q18: Y | R18: 1
A20: AI-alone by fracture location
A21: Upper limb | B21: Sensitivity | C21: 0.913 | D21: 0.871 | E21: 0.942 | F21: 0.716 | G21: 0.977 | H21: 9 | I21: 124 | J21: =E21-D21 -> 0.071 | K21: 1 | L21: =(E21-D21)/(G21-F21) -> 0.27203065 | M21: 3 | N21: 0 | O21: 73 | P21: 4 | Q21: Y | R21: 1 | S21: IV
B22: Specificity | C22: 0.886 | D22: 0.868 | E22: 0.902 | F22: 0.826 | G22: 0.927 | H22: 9 | I22: 124 | J22: =E22-D22 -> 0.034 | K22: 1 | L22: =(E22-D22)/(G22-F22) -> 0.33663366 | M22: 2 | N22: 0 | O22: 73 | P22: 4 | Q22: Partial Y - lower bounds wider in narrative synthesis | R22: 2
A23: Lower limb | B23: Sensitivity | C23: 0.896 | D23: 0.853 | E23: 0.927 | F23: 0.698 | G23: 0.97 | H23: 5 | I23: 63 | J23: =E23-D23 -> 0.074 | K23: 1 | L23: =(E23-D23)/(G23-F23) -> 0.27205882 | M23: 3 | N23: 0 | O23: 80 | P23: 4 | Q23: Y | R23: 1 | S23: IV
B24: Specificity | C24: 0.902 | D24: 0.871 | E24: 0.927 | F24: 0.78 | G24: 0.96 | H24: 5 | I24: 63 | J24: =E24-D24 -> 0.056 | K24: 1 | L24: =(E24-D24)/(G24-F24) -> 0.31111111 | M24: 2 | N24: 0 | O24: 80 | P24: 4 | Q24: Y | R24: 1
A25: Axial | B25: Sensitivity | C25: 0.855 | D25: 0.795 | E25: 0.899 | F25: 0.641 | G25: 0.951 | H25: 8 | I25: 59 | J25: =E25-D25 -> 0.104 | K25: 2 | L25: =(E25-D25)/(G25-F25) -> 0.33548387 | M25: 2 | N25: 0 | O25: 63 | P25: 4 | Q25: Y | R25: 1 | S25: IV
B26: Specificity | C26: 0.92 | D26: 0.877 | E26: 0.949 | F26: 0.773 | G26: 0.975 | H26: 8 | I26: 59 | J26: =E26-D26 -> 0.072 | K26: 1 | L26: =(E26-D26)/(G26-F26) -> 0.35643564 | M26: 2 | N26: 0 | O26: 63 | P26: 4 | Q26: Y | R26: 1
A27: Skull/facial | B27: Sensitivity | C27: 0.923 | D27: 0.761 | E27: 0.978 | F27: 0.442 | G27: 0.995 | H27: 4 | I27: 23 | J27: =E27-D27 -> 0.217 | K27: 4 | L27: =(E27-D27)/(G27-F27) -> 0.39240506 | M27: 2 | N27: 0 | O27: 0 | P27: 3 | Q27: Y | R27: 1 | S27: IV
B28: Specificity | C28: 0.871 | D28: 0.759 | E28: 0.935 | F28: 0.615 | G28: 0.966 | H28: 4 | I28: 23 | J28: =E28-D28 -> 0.176 | K28: 3 | L28: =(E28-D28)/(G28-F28) -> 0.5014245 | M28: 1 | N28: 0 | O28: 0 | P28: 3 | Q28: Y | R28: 1
A30: AI-alone by validation type
A31: Internal | B31: Sensitivity | C31: 0.895 | D31: 0.813 | E31: 0.943 | F31: 0.735 | G31: 0.963 | H31: 3 | I31: 85 | J31: =E31-D31 -> 0.13 | K31: 2 | L31: =(E31-D31)/(G31-F31) -> 0.57017544 | M31: 1 | N31: 0 | O31: 33 | P31: 3 | Q31: Y | R31: 1 | S31: IV
B32: Specificity | C32: 0.909 | D32: 0.74 | E32: 0.973 | F32: 0.74 | G32: 0.973 | H32: 2 | I32: 85 | J32: =E32-D32 -> 0.233 | K32: 4 | L32: =(E32-D32)/(G32-F32) -> 1 | M32: 1 | N32: 0 | O32: 33 | P32: 3 | Q32: Y | R32: 1
A33: External | B33: Sensitivity | C33: 0.902 | D33: 0.872 | E33: 0.925 | F33: 0.805 | G33: 0.953 | H33: 4 | I33: 56 | J33: =E33-D33 -> 0.053 | K33: 1 | L33: =(E33-D33)/(G33-F33) -> 0.35810811 | M33: 2 | N33: 0 | O33: 50 | P33: 4 | Q33: Y | R33: 1 | S33: IV
B34: Specificity | C34: 0.897 | D34: 0.885 | E34: 0.908 | F34: 0.885 | G34: 0.908 | H34: 3 | I34: 56 | J34: =E34-D34 -> 0.023 | K34: 2 | L34: =(E34-D34)/(G34-F34) -> 1 | M34: 1 | N34: 0 | O34: 50 | P34: 4 | Q34: Y | R34: 1
A36: AI-alone by population
A37: Adult | B37: Sensitivity | C37: 0.905 | D37: 0.87 | E37: 0.931 | F37: 0.87 | G37: 0.931 | H37: 3 | I37: 111 | J37: =E37-D37 -> 0.061 | K37: 1 | L37: =(E37-D37)/(G37-F37) -> 1 | M37: 1 | N37: 0 | O37: 50 | P37: 4 | Q37: Y | R37: 1 | S37: IV
B38: Specificity | C38: 0.941 | D38: 0.913 | E38: 0.96 | F38: 0.909 | G38: 0.962 | H38: 3 | I38: 111 | J38: =E38-D38 -> 0.047 | K38: 1 | L38: =(E38-D38)/(G38-F38) -> 0.88679245 | M38: 1 | N38: 0 | O38: 50 | P38: 4 | Q38: Y | R38: 1
A39: Paediatric | B39: Sensitivity | C39: 0.918 | D39: 0.553 | E39: 0.99 | F39: 0.475 | G39: 0.993 | H39: 2 | I39: 12 | J39: =E39-D39 -> 0.437 | K39: 5 | L39: =(E39-D39)/(G39-F39) -> 0.84362934 | M39: 1 | N39: 0 | O39: 50 | P39: 4 | Q39: Y | R39: 1 | S39: IV
B40: Specificity | C40: 0.884 | D40: 0.552 | E40: 0.979 | F40: 0.552 | G40: 0.979 | H40: 2 | I40: 12 | J40: =E40-D40 -> 0.427 | K40: 5 | L40: =(E40-D40)/(G40-F40) -> 1 | M40: 1 | N40: 0 | O40: 50 | P40: 4 | Q40: Y | R40: 1

Sheet GRADE
D3: GRADE assessment (Domains 1, 2, 3, 4) | H3: Interim GRADE | I3: Inconsistency | K3: Outcome | L3: Interim GRADE | M3: Imprecision | Q3: Outcome | R3: Final GRADE
C4: Number of contributing meta-analyses | D4: High | E4: Moderate | F4: Low | G4: Very low | H4: (Modal tier) | M4: 95% CI lower | N4: 95% CI upper | O4: 95% CI width | P4: Narrow (<0.15)?
A5: Group | B5: Finding | I5: % of 95% PI covered by 95% CI | J5: >30%?
A6: Overall AI performance | B6: Sensitivity | C6: 21 | D6: 0 | E6: 3 | F6: 7 | G6: 11 | H6: Very low | I6: ='Credibility assessment'!L3 -> 0.13592233 | J6: N | K6: Downgrade | L6: Very low | M6: 0.882 | N6: 0.91 | O6: =N6-M6 -> 0.028 | P6: Y | Q6: No change | R6: Very low
B7: Specificity | C7: 19 | D7: 0 | E7: 3 | F7: 6 | G7: 10 | H7: Very low | I7: ='Credibility assessment'!L4 -> 0.1984127 | J7: N | K7: Downgrade | L7: Very low | M7: 0.891 | N7: 0.916 | O7: =N7-M7 -> 0.025 | P7: Y | Q7: No change
A8: Overall clinician performance | B8: Sensitivity | C8: 7 | D8: 1 | E8: 0 | F8: 4 | G8: 2 | H8: Low | I8: ='Credibility assessment'!L5 -> 0.3056872 | J8: Y | K8: No change | L8: Low | M8: 0.781 | N8: 0.95 | O8: =N8-M8 -> 0.169 | P8: N | Q8: Downgrade | R8: Very low
B9: Specificity | C9: 6 | D9: 1 | E9: 0 | F9: 4 | G9: 1 | H9: Low | I9: ='Credibility assessment'!L6 -> 0.56097561 | J9: Y | K9: No change | L9: Low | M9: 0.92 | N9: 0.943 | O9: =N9-M9 -> 0.023 | P9: Y | Q9: No change
A10: Overall AI-as-assistant performance | B10: Sensitivity | C10: 4 | D10: 1 | E10: 0 | F10: 3 | G10: 0 | H10: Low | I10: ='Credibility assessment'!L7 -> 0.50805271 | J10: Y | K10: No change | L10: Low | M10: 0.882 | N10: 0.906 | O10: =N10-M10 -> 0.024 | P10: Y | Q10: No change | R10: Low
B11: Specificity | C11: 4 | D11: 1 | E11: 0 | F11: 3 | G11: 0 | H11: Low | I11: ='Credibility assessment'!L8 -> 0.512 | J11: Y | K11: No change | L11: Low | M11: 0.899 | N11: 0.963 | O11: =N11-M11 -> 0.064 | P11: Y | Q11: No change
A13: AI-alone by modality
A14: Radiographs | B14: Sensitivity | C14: 13 | D14: 1 | E14: 1 | F14: 6 | G14: 5 | H14: Low | I14: ='Credibility assessment'!L11 -> 0.18577075 | J14: N | K14: Downgrade | L14: Very low | M14: 0.878 | N14: 0.925 | O14: =N14-M14 -> 0.047 | P14: Y | Q14: No change | R14: Very low
B15: Specificity | C15: 13 | D15: 1 | E15: 1 | F15: 6 | G15: 5 | H15: Low | I15: ='Credibility assessment'!L12 -> 0.1875 | J15: N | K15: Downgrade | L15: Very low | M15: 0.882 | N15: 0.906 | O15: =N15-M15 -> 0.024 | P15: Y | Q15: No change
A16: CT | B16: Sensitivity | C16: 7 | D16: 1 | E16: 1 | F16: 3 | G16: 2 | H16: Low | I16: ='Credibility assessment'!L13 -> 0.61904762 | J16: Y | K16: No change | L16: Low | M16: 0.838 | N16: 0.89 | O16: =N16-M16 -> 0.052 | P16: Y | Q16: No change | R16: Low
B17: Specificity | C17: 5 | D17: 1 | E17: 1 | F17: 2 | G17: 1 | H17: Low | I17: ='Credibility assessment'!L14 -> 0.43010753 | J17: N | K17: No change | L17: Low | M17: 0.885 | N17: 0.965 | O17: =N17-M17 -> 0.08 | P17: Y | Q17: No change
A18: MRI | B18: Sensitivity | C18: 1 | D18: 0 | E18: 1 | F18: 0 | G18: 0 | H18: Moderate | I18: ='Credibility assessment'!L15 -> N/A | J18: N | K18: Downgrade | L18: Low | M18: 0.83 | N18: 0.95 | O18: =N18-M18 -> 0.12 | P18: Y | Q18: No change | R18: Low
B19: Specificity | C19: 1 | D19: 0 | E19: 1 | F19: 0 | G19: 0 | H19: Moderate | I19: ='Credibility assessment'!L16 -> N/A | J19: N | K19: Downgrade | L19: Low | M19: 0.84 | N19: 0.93 | O19: =N19-M19 -> 0.09 | P19: Y | Q19: No change
A20: DEXA | B20: Sensitivity | C20: 1 | D20: 1 | E20: 0 | F20: 0 | G20: 0 | H20: High | I20: ='Credibility assessment'!L17 -> N/A | J20: N | K20: Downgrade | L20: Moderate | M20: 0.8 | N20: 0.88 | O20: =N20-M20 -> 0.08 | P20: Y | Q20: No change | R20: Moderate
B21: Specificity | C21: 1 | D21: 1 | E21: 0 | F21: 0 | G21: 0 | H21: High | I21: ='Credibility assessment'!L18 -> N/A | J21: N | K21: Downgrade | L21: Moderate | M21: 0.89 | N21: 0.96 | O21: =N21-M21 -> 0.07 | P21: Y | Q21: No change
A23: AI-alone by fracture location
A24: Upper limb | B24: Sensitivity | C24: 9 | D24: 0 | E24: 2 | F24: 2 | G24: 5 | H24: Very low | I24: ='Credibility assessment'!L21 -> 0.27203065 | J24: N | K24: Downgrade | L24: Very low | M24: 0.871 | N24: 0.942 | O24: =N24-M24 -> 0.071 | P24: Y | Q24: No change | R24: Very low
B25: Specificity | C25: 9 | D25: 0 | E25: 2 | F25: 2 | G25: 5 | H25: Very low | I25: ='Credibility assessment'!L22 -> 0.33663366 | J25: Y | K25: No change | L25: Very low | M25: 0.868 | N25: 0.902 | O25: =N25-M25 -> 0.034 | P25: Y | Q25: No change
A26: Lower limb | B26: Sensitivity | C26: 5 | D26: 0 | E26: 1 | F26: 1 | G26: 2 | H26: Very low | I26: ='Credibility assessment'!L23 -> 0.27205882 | J26: N | K26: Downgrade | L26: Very low | M26: 0.853 | N26: 0.927 | O26: =N26-M26 -> 0.074 | P26: Y | Q26: No change | R26: Very low
B27: Specificity | C27: 5 | D27: 0 | E27: 1 | F27: 1 | G27: 2 | H27: Very low | I27: ='Credibility assessment'!L24 -> 0.31111111 | J27: Y | K27: No change | L27: Very low | M27: 0.871 | N27: 0.927 | O27: =N27-M27 -> 0.056 | P27: Y | Q27: No change
A28: Axial | B28: Sensitivity | C28: 8 | D28: 0 | E28: 2 | F28: 4 | G28: 2 | H28: Low | I28: ='Credibility assessment'!L25 -> 0.33548387 | J28: Y | K28: No change | L28: Low | M28: 0.795 | N28: 0.899 | O28: =N28-M28 -> 0.104 | P28: Y | Q28: No change | R28: Low
B29: Specificity | C29: 8 | D29: 0 | E29: 2 | F29: 2 | G29: 2 | H29: Low | I29: ='Credibility assessment'!L26 -> 0.35643564 | J29: Y | K29: No change | L29: Low | M29: 0.877 | N29: 0.949 | O29: =N29-M29 -> 0.072 | P29: Y | Q29: No change
A30: Skull/facial | B30: Sensitivity | C30: 4 | D30: 0 | E30: 0 | F30: 1 | G30: 2 | H30: Very low | I30: ='Credibility assessment'!L27 -> 0.39240506 | J30: Y | K30: No change | L30: Very low | M30: 0.761 | N30: 0.978 | O30: =N30-M30 -> 0.217 | P30: Y | Q30: Downgrade | R30: Very low
B31: Specificity | C31: 4 | D31: 0 | E31: 0 | F31: 1 | G31: 2 | H31: Very low | I31: ='Credibility assessment'!L28 -> 0.5014245 | J31: Y | K31: No change | L31: Very low | M31: 0.759 | N31: 0.935 | O31: =N31-M31 -> 0.176 | P31: Y | Q31: No change
A33: AI-alone by validation type
A34: Internal | B34: Sensitivity | C34: 3 | D34: 0 | E34: 0 | F34: 1 | G34: 2 | H34: Very low | I34: ='Credibility assessment'!L31 -> 0.57017544 | J34: Y | K34: No change | L34: Very low | M34: 0.813 | N34: 0.943 | O34: =N34-M34 -> 0.13 | P34: Y | Q34: No change | R34: Very low
B35: Specificity | C35: 2 | D35: 0 | E35: 0 | F35: 1 | G35: 1 | H35: Very low | I35: ='Credibility assessment'!L32 -> 1 | J35: Y | K35: No change | L35: Very low | M35: 0.74 | N35: 0.973 | O35: =N35-M35 -> 0.233 | P35: N | Q35: Downgrade
A36: External | B36: Sensitivity | C36: 4 | D36: 0 | E36: 0 | F36: 1 | G36: 3 | H36: Very low | I36: ='Credibility assessment'!L33 -> 0.35810811 | J36: Y | K36: No change | L36: Very low | M36: 0.872 | N36: 0.925 | O36: =N36-M36 -> 0.053 | P36: Y | Q36: No change | R36: Very low
B37: Specificity | C37: 3 | D37: 0 | E37: 0 | F37: 1 | G37: 2 | H37: Very low | I37: ='Credibility assessment'!L34 -> 1 | J37: Y | K37: No change | L37: Very low | M37: 0.885 | N37: 0.908 | O37: =N37-M37 -> 0.023 | P37: Y | Q37: No change
A39: AI-alone by population
A40: Adult | B40: Sensitivity | C40: 3 | D40: 0 | E40: 1 | F40: 0 | G40: 2 | H40: Very low | I40: ='Credibility assessment'!L37 -> 1 | J40: Y | K40: No change | L40: Very low | M40: 0.87 | N40: 0.931 | O40: =N40-M40 -> 0.061 | P40: Y | Q40: No change | R40: Very low
B41: Specificity | C41: 3 | D41: 0 | E41: 1 | F41: 0 | G41: 2 | H41: Very low | I41: ='Credibility assessment'!L38 -> 0.88679245 | J41: Y | K41: No change | L41: Very low | M41: 0.913 | N41: 0.96 | O41: =N41-M41 -> 0.047 | P41: Y | Q41: No change
A42: Paediatric | B42: Sensitivity | C42: 2 | D42: 0 | E42: 0 | F42: 1 | G42: 1 | H42: Very low | I42: ='Credibility assessment'!L39 -> 0.84362934 | J42: Y | K42: No change | L42: Very low | M42: 0.553 | N42: 0.99 | O42: =N42-M42 -> 0.437 | P42: N | Q42: Downgrade | R42: Very low
B43: Specificity | C43: 2 | D43: 0 | E43: 0 | F43: 1 | G43: 1 | H43: Very low | I43: ='Credibility assessment'!L40 -> 1 | J43: Y | K43: No change | L43: Very low | M43: 0.552 | N43: 0.979 | O43: =N43-M43 -> 0.427 | P43: N | Q43: Downgrade

Sheet GRADE by MA, main
A1: Outcome | C1: Meta-analysis | D1: Source of risk of bias information | E1: Number of contributing primary studies | F1: Starting level | G1: Risk of bias | K1: Outcome | M1: Publication bias | N1: Outcome | O1: Interim GRADE | P1: Outcome | Q1: Indirectness | S1: Outcome | U1: Final GRADE | V1: Outcome | W1: Indirectness | AA1: Outcome | AC1: Final GRADE | AD1: Outcome | AE1: Indirectness | AI1: Outcome | AK1: Final GRADE
G2: Low | H2: Moderate | I2: High | J2: % low risk | K2: Classification | L2: GRADE | M2: Yes/No/NR | N2: GRADE | Q2: Imaging | R2: Fracture location | S2: How many points | T2: GRADE | W2: Population | X2: Imaging | Y2: Fracture location | Z2: Appropriate reference | AA2: How many points | AB2: GRADE | AE2: Population | AF2: Imaging | AG2: Fracture location | AH2: Appropriate reference | AI2: How many points | AJ2: GRADE
B3: Finding
A4: Start here: | B4: Sensitivity | C4: Beculic | D4: QUADAS-2 | E4: 17 | F4: Low | G4: 8 | H4: 3 | I4: 0 | J4: =G4/E4 -> 0.47058824 | K4: Unclear | L4: Downgrade | M4: N | N4: No change | O4: Very low | P4: AI-alone | Q4: Y | R4: Vertebral only | S4: 2 | T4: No change | U4: Very low | V4: Clinician performance | AD4: AI-assist
B5: Specificity | C5: Beculic | D5: QUADAS-2 | E5: 17 | F5: Low | G5: 8 | H5: 3 | I5: 0 | J5: =G5/E5 -> 0.47058824 | K5: Unclear | L5: Downgrade | M5: N | N5: No change | O5: Very low | Q5: Y | R5: Vertebral only | S5: 2 | T5: No change | U5: Very low
B6: Sensitivity | C6: Binh | D6: QUADAS-2 | E6: 6 | F6: Low | G6: 5 | H6: 1 | I6: 0 | J6: =G6/E6 -> 0.83333333 | K6: Y | L6: Upgrade | M6: N | N6: No change | O6: Moderate | Q6: Radiograph only | R6: Elbow only | S6: 0 | T6: Downgrade | U6: Low
B7: Specificity | C7: Binh | D7: QUADAS-2 | E7: 6 | F7: Low | G7: 5 | H7: 1 | I7: 0 | J7: =G7/E7 -> 0.83333333 | K7: Y | L7: Upgrade | M7: N | N7: No change | O7: Moderate | Q7: Radiograph only | R7: Elbow only | S7: 0 | T7: Downgrade | U7: Low
B8: Sensitivity | C8: Dashti | D8: QUADAS-2 | E8: 5 | F8: Low | G8: 1 | H8: 3 | I8: 1 | J8: =G8/E8 -> 0.2 | K8: N | L8: Downgrade | M8: N | N8: No change | O8: Very low | Q8: Radiograph only | R8: Mandible only | S8: 0 | T8: Downgrade | U8: Very low
B9: Specificity | C9: Dashti | D9: QUADAS-2 | E9: 5 | F9: Low | G9: 1 | H9: 3 | I9: 1 | J9: =G9/E9 -> 0.2 | K9: N | L9: Downgrade | M9: N | N9: No change | O9: Very low | Q9: Radiograph only | R9: Mandible only | S9: 0 | T9: Downgrade | U9: Very low
B10: Sensitivity | C10: Den Hengst | D10: MINORS | E10: 20 | F10: Low | G10: 4 | H10: NR | I10: NR | J10: =G10/E10 -> 0.2 | K10: Y | L10: Upgrade | M10: NR | N10: Downgrade | O10: Low | Q10: CT only | R10: Rib only | S10: 1 | T10: Downgrade | U10: Very low | W10: Y | X10: CT only | Y10: Rib only | Z10: Y | AA10: 2 | AB10: No change | AC10: Very low
B11: Specificity | C11: Den Hengst | E11: 20 | AC11: Very low
B12: Sensitivity | C12: Hansen | D12: QUADAS-2 | E12: 8 | F12: Low | G12: 5 | H12: 3 | I12: 0 | J12: =G12/E12 -> 0.625 | K12: N | L12: Upgrade | M12: NR | N12: Downgrade | O12: Low | Q12: Radiograph only | R12: Wrist only | S12: 1 | T12: Downgrade | U12: Very low
B13: Specificity | C13: Hansen | D13: QUADAS-2 | E13: 8 | F13: Low | G13: 5 | H13: 3 | I13: 0 | J13: =G13/E13 -> 0.625 | K13: N | L13: Upgrade | M13: NR | N13: Downgrade | O13: Low | Q13: Radiograph only | R13: Wrist only | S13: 1 | T13: Downgrade | U13: Very low
B14: Sensitivity | C14: Husarek | D14: QUADAS-2 | E14: 17 | F14: Low | G14: 6 | H14: 9 | I14: 2 | J14: =G14/E14 -> 0.35294118 | K14: Y | L14: Downgrade | M14: NR | N14: Downgrade | O14: Very low | Q14: Radiograph only | R14: Y | S14: 2 | T14: No change | U14: Very low | W14: Y | X14: Radiographs only | Y14: Y | Z14: Y | AA14: 3 | AB14: Upgrade | AC14: Low | AE14: Y | AF14: Radiographs only | AG14: Y | AH14: Y | AI14: 3 | AJ14: Upgrade | AK14: Low
B15: Specificity | C15: Husarek | D15: QUADAS-2 | E15: 17 | F15: Low | G15: 6 | H15: 9 | I15: 2 | J15: =G15/E15 -> 0.35294118 | K15: Y | L15: Downgrade | M15: NR | N15: Downgrade | O15: Very low | Q15: Radiograph only | R15: Y | S15: 2 | T15: No change | U15: Very low | W15: Y | X15: Radiographs only | Y15: Y | Z15: Y | AA15: 3 | AB15: Upgrade | AC15: Low | AE15: Y | AF15: Radiographs only | AG15: Y | AH15: Y | AI15: 3 | AJ15: Upgrade | AK15: Low
B16: Sensitivity | C16: Ju | D16: QUADAS-2 | E16: 11 | F16: Low | G16: 4 | H16: 0 | I16: 7 | J16: =G16/E16 -> 0.36363636 | K16: N | L16: Downgrade | M16: N | N16: No change | O16: Very low | Q16: Y | R16: Facial only | S16: 2 | T16: No change | U16: Very low
B17: Specificity | C17: Ju | D17: QUADAS-2 | E17: 11 | F17: Low | G17: 4 | H17: 0 | I17: 7 | J17: =G17/E17 -> 0.36363636 | K17: N | L17: Downgrade | M17: N | N17: No change | O17: Very low | Q17: Y | R17: Facial only | S17: 2 | T17: No change | U17: Very low
B18: Sensitivity | C18: Jung | D18: QUADAS-2 | E18: 57 | F18: Low | G18: 40 | H18: 9 | I18: 0 | J18: =G18/E18 -> 0.70175439 | K18: Y | L18: Upgrade | M18: Y | N18: Downgrade | O18: Low | Q18: Y | R18: Y | S18: 3 | T18: Upgrade | U18: Moderate
B19: Specificity | C19: Jung | D19: QUADAS-2 | E19: 57 | F19: Low | G19: 40 | H19: 9 | I19: 0 | J19: =G19/E19 -> 0.70175439 | K19: Y | L19: Upgrade | M19: Y | N19: Downgrade | O19: Low | Q19: Y | R19: Y | S19: 3 | T19: Upgrade | U19: Moderate
B20: Sensitivity | C20: Kraus | D20: QUADAS-2 | E20: 7 | F20: Low | G20: 1 | H20: 8 | I20: 1 | J20: =G20/E20 -> 0.14285714 | K20: N | L20: Downgrade | M20: NR | N20: Downgrade | O20: Very low | Q20: Radiograph only | R20: Scaphoid only | S20: 1 | T20: Downgrade | U20: Very low
B21: Specificity | C21: Kraus | D21: QUADAS-2 | E21: 7 | F21: Low | G21: 1 | H21: 8 | I21: 1 | J21: =G21/E21 -> 0.14285714 | K21: N | L21: Downgrade | M21: NR | N21: Downgrade | O21: Very low | Q21: Radiograph only | R21: Scaphoid only | S21: 1 | T21: Downgrade | U21: Very low
B22: Sensitivity | C22: Kuo | D22: PROBAST | E22: 32 | F22: Low | G22: 9 | H22: 1 | I22: 22 | J22: =G22/E22 -> 0.28125 | K22: N | L22: Downgrade | M22: N | N22: No change | O22: Very low | Q22: Y | R22: Y | S22: 3 | T22: Upgrade | U22: Low | W22: Y | X22: Y | Y22: Y | Z22: Y | AA22: 4 | AB22: Upgrade | AC22: Low | AE22: Y | AF22: Y | AG22: Y | AH22: Y | AI22: 4 | AJ22: Upgrade | AK22: Low
B23: Specificity | C23: Kuo | D23: PROBAST | E23: 32 | F23: Low | G23: 9 | H23: 1 | I23: 22 | J23: =G23/E23 -> 0.28125 | K23: N | L23: Downgrade | M23: N | N23: No change | O23: Very low | Q23: Y | R23: Y | S23: 3 | T23: Upgrade | U23: Low | W23: Y | X23: Y | Y23: Y | Z23: Y | AA23: 4 | AB23: Upgrade | AC23: Low | AE23: Y | AF23: Y | AG23: Y | AH23: Y | AI23: 4 | AJ23: Upgrade | AK23: Low
B24: Sensitivity | C24: Li | D24: QUADAS-2 | E24: 81 | F24: Low | G24: 81 | H24: 0 | I24: 0 | J24: =G24/E24 -> 1 | K24: Y | L24: Upgrade | M24: N | N24: No change | O24: Moderate | Q24: Y | R24: Vertebral only | S24: 1 | T24: Downgrade | U24: Low
B25: Specificity | C25: Li | D25: QUADAS-2 | E25: 81 | F25: Low | G25: 81 | H25: 0 | I25: 0 | J25: =G25/E25 -> 1 | K25: Y | L25: Upgrade | M25: N | N25: No change | O25: Moderate | Q25: Y | R25: Vertebral only | S25: 1 | T25: Downgrade | U25: Low
B26: Sensitivity | C26: Lopez-Melia | D26: QUADAS-2 | E26: 7 | F26: Low | G26: 5 | H26: 1 | I26: 0 | J26: =G26/E26 -> 0.71428571 | K26: Y | L26: Upgrade | M26: NR | N26: Downgrade | O26: Low | Q26: CT only | R26: Rib only | S26: 1 | T26: Downgrade | U26: Very low
B27: Specificity | C27: Lopez-Melia | E27: 7
B28: Sensitivity | C28: Mellon | D28: QUADAS-2 | E28: 16 | F28: Low | G28: 8 | H28: 4 | I28: 4 | J28: =G28/E28 -> 0.5 | K28: N | L28: Downgrade | M28: NR | N28: Downgrade | O28: Very low | Q28: Radiograph only | R28: Upper limb only | S28: 1 | T28: Downgrade | U28: Very low
B29: Specificity | C29: Mellon | D29: QUADAS-2 | E29: 16 | F29: Low | G29: 8 | H29: 4 | I29: 4 | J29: =G29/E29 -> 0.5 | K29: N | L29: Downgrade | M29: NR | N29: Downgrade | O29: Very low | Q29: Radiograph only | R29: Upper limb only | S29: 1 | T29: Downgrade | U29: Very low
B30: Sensitivity | C30: Nowroozi | D30: QUADAS-2 | E30: 83 | F30: Low | G30: 3 | H30: Unclear | I30: Unclear | J30: =G30/E30 -> 0.036144578 | K30: N | L30: Downgrade | M30: N | N30: No change | O30: Very low | Q30: Radiograph only | R30: Y | S30: 2 | T30: No change | U30: Very low | W30: Y | X30: Radiographs only | Y30: Y | Z30: Y | AA30: 3 | AB30: Upgrade | AC30: Low
B31: Specificity | C31: Nowroozi | D31: QUADAS-2 | E31: 83 | F31: Low | G31: 3 | H31: Unclear | I31: Unclear | J31: =G31/E31 -> 0.036144578 | K31: N | L31: Downgrade | M31: N | N31: No change | O31: Very low | Q31: Radiograph only | R31: Y | S31: 2 | T31: No change | U31: Very low | W31: Y | X31: Radiographs only | Y31: Y | Z31: Y | AA31: 3 | AB31: Upgrade | AC31: Low
B32: Sensitivity | C32: Ramadanov | D32: QUADAS-2 | E32: 11 | F32: Low | G32: 4 | H32: 5 | I32: 2 | J32: =G32/E32 -> 0.36363636 | K32: Y | L32: Upgrade | M32: Y | N32: Downgrade | O32: Low | Q32: Radiograph only | R32: Femoral neck only | S32: 1 | T32: Downgrade | U32: Very low
B33: Specificity | C33: Ramadanov | D33: QUADAS-2 | E33: 11 | F33: Low | G33: 4 | H33: 5 | I33: 2 | J33: =G33/E33 -> 0.36363636 | K33: Y | L33: Upgrade | M33: Y | N33: Downgrade | O33: Low | Q33: Radiograph only | R33: Femoral neck only | S33: 1 | T33: Downgrade | U33: Very low
B34: Sensitivity | C34: Sharifi | D34: QUADAS-2 | E34: 11 | F34: Low | G34: 1 | H34: 4 | I34: 6 | J34: =G34/E34 -> 0.090909091 | K34: N | L34: Downgrade | M34: N | N34: No change | O34: Very low | Q34: CT only | R34: Skull only | S34: 1 | T34: Downgrade | U34: Very low
B35: Specificity | C35: Sharifi | D35: QUADAS-2 | E35: 11 | F35: Low | G35: 1 | H35: 4 | I35: 6 | J35: =G35/E35 -> 0.090909091 | K35: N | L35: Downgrade | M35: N | N35: No change | O35: Very low | Q35: CT only | R35: Skull only | S35: 1 | T35: Downgrade | U35: Very low
B36: Sensitivity | C36: Suen | D36: QUADAS-2 | E36: 20 | F36: Low | G36: 16 | H36: 4 | I36: 0 | J36: =G36/E36 -> 0.8 | K36: Y | L36: Upgrade | M36: NR | N36: Downgrade | O36: Low | Q36: Radiograph only | R36: Wrist only | S36: 1 | T36: Downgrade | U36: Very low | W36: Y | X36: Radiographs only | Y36: Wrist only | Z36: Y | AA36: 2 | AB36: No change | AC36: Very low
B37: Specificity | C37: Suen | D37: QUADAS-2 | E37: 20 | F37: Low | G37: 16 | H37: 4 | I37: 0 | J37: =G37/E37 -> 0.8 | K37: Y | L37: Upgrade | M37: NR | N37: Downgrade | O37: Low | Q37: Radiograph only | R37: Wrist only | S37: 1 | T37: Downgrade | U37: Very low | W37: Y | X37: Radiographs only | Y37: Wrist only | Z37: Y | AA37: 2 | AB37: No change | AC37: Very low
B38: Sensitivity | C38: Wong | D38: QUADAS-2 | E38: 32 | F38: Low | G38: 13 | H38: 15 | I38: 4 | J38: =G38/E38 -> 0.40625 | K38: N | L38: Downgrade | M38: Y | N38: Downgrade | O38: Very low | Q38: Y | R38: Hand and wrist only | S38: 2 | T38: No change | U38: Very low | W38: Y | X38: Y | Y38: Hand and wrist only | Z38: Y | AA38: 3 | AB38: Upgrade | AC38: Low | AE38: Y | AF38: Y | AG38: Hand and wrist only | AH38: Y | AI38: 3 | AJ38: Upgrade | AK38: Low
B39: Specificity | C39: Wong | D39: QUADAS-2 | E39: 32 | F39: Low | G39: 13 | H39: 15 | I39: 4 | J39: =G39/E39 -> 0.40625 | K39: N | L39: Downgrade | M39: Y | N39: Downgrade | O39: Very low | Q39: Y | R39: Hand and wrist only | S39: 2 | T39: No change | U39: Very low | W39: Y | X39: Y | Y39: Hand and wrist only | Z39: Y | AA39: 3 | AB39: Upgrade | AC39: Low | AE39: Y | AF39: Y | AG39: Hand and wrist only | AH39: Y | AI39: 3 | AJ39: Upgrade | AK39: Low
B40: Sensitivity | C40: van den Broek | D40: QUADAS-2 | E40: 12 | F40: Low | G40: 10 | H40: 2 | I40: 0 | J40: =G40/E40 -> 0.83333333 | K40: Y | L40: Upgrade | M40: Y | N40: Downgrade | O40: Low | Q40: CT only | R40: Rib only | S40: 1 | T40: Downgrade | U40: Very low
...

Sheet GRADE by MA, modality
A1: Outcome | C1: Meta-analysis | D1: Source of risk of bias information | E1: Number of contributing primary studies | F1: Starting level | G1: Risk of bias | K1: Outcome | M1: Publication bias | N1: Outcome | O1: Interim GRADE | P1: Outcome | Q1: Indirectness | S1: Outcome | U1: Final GRADE | V1: Outcome | W1: Indirectness | Y1: Outcome | AA1: Final GRADE | AB1: Outcome | AC1: Indirectness | AE1: Outcome | AG1: Final GRADE | AH1: Outcome | AI1: Indirectness | AK1: Outcome | AM1: Final GRADE | AN1: Outcome | AO1: Indirectness | AQ1: Outcome | AS1: Final GRADE
G2: Low | H2: Moderate | I2: High | J2: % low risk | K2: Classiciation | L2: GRADE | M2: Yes/No/NR | N2: GRADE | Q2: Population | R2: Fracture location | S2: How many points | T2: GRADE | W2: Population | X2: Fracture location | Y2: How many points | Z2: GRADE | AC2: Population | AD2: Fracture location | AE2: How many points | AF2: GRADE | AI2: Population | AJ2: Fracture location | AK2: How many points | AL2: GRADE | AO2: Population | AP2: Fracture location | AQ2: How many points | AR2: GRADE
B3: Finding
A4: Start here: | B4: Sensitivity | C4: Beculic | D4: QUADAS-2 | E4: 17 | F4: Low | G4: 8 | H4: 3 | I4: 0 | J4: =G4/E4 -> 0.47058824 | K4: Unclear | L4: Downgrade | M4: N | N4: No change | O4: Very low | P4: Radiographs | V4: CT | AB4: DEXA | AH4: MRI | AN4: Added tabular
B5: Specificity | C5: Beculic | D5: QUADAS-2 | E5: 17 | F5: Low | G5: 8 | H5: 3 | I5: 0 | J5: =G5/E5 -> 0.47058824 | K5: Unclear | L5: Downgrade | M5: N | N5: No change | O5: Very low
B6: Sensitivity | C6: Binh | D6: QUADAS-2 | E6: 6 | F6: Low | G6: 5 | H6: 1 | I6: 0 | J6: =G6/E6 -> 0.83333333 | K6: Y | L6: Upgrade | M6: N | N6: No change | O6: Moderate | Q6: N | R6: Elbow only | S6: 0 | T6: Downgrade | U6: Low
B7: Specificity | C7: Binh | D7: QUADAS-2 | E7: 6 | F7: Low | G7: 5 | H7: 1 | I7: 0 | J7: =G7/E7 -> 0.83333333 | K7: Y | L7: Upgrade | M7: N | N7: No change | O7: Moderate | Q7: N | R7: Elbow only | S7: 0 | T7: Downgrade | U7: Low
B8: Sensitivity | C8: Dashti | D8: QUADAS-2 | E8: 5 | F8: Low | G8: 1 | H8: 3 | I8: 1 | J8: =G8/E8 -> 0.2 | K8: N | L8: Downgrade | M8: N | N8: No change | O8: Very low | Q8: Y | R8: Mandible only | S8: 1 | T8: No change | U8: Very low
B9: Specificity | C9: Dashti | D9: QUADAS-2 | E9: 5 | F9: Low | G9: 1 | H9: 3 | I9: 1 | J9: =G9/E9 -> 0.2 | K9: N | L9: Downgrade | M9: N | N9: No change | O9: Very low | Q9: Y | R9: Mandible only | S9: 1 | T9: No change | U9: Very low
B10: Sensitivity | C10: Den Hengst | D10: MINORS | E10: 20 | F10: Low | G10: 4 | H10: NR | I10: NR | J10: =G10/E10 -> 0.2 | K10: Y | L10: Upgrade | M10: NR | N10: Downgrade | O10: Low | W10: Y | X10: Rib only | Y10: 1 | Z10: No change | AA10: Low
B11: Specificity | C11: Den Hengst | E11: 20
B12: Sensitivity | C12: Hansen | D12: QUADAS-2 | E12: 8 | F12: Low | G12: 5 | H12: 3 | I12: 0 | J12: =G12/E12 -> 0.625 | K12: N | L12: Upgrade | M12: NR | N12: Downgrade | O12: Low | Q12: Adults only | R12: Wrist only | S12: 0 | T12: Downgrade | U12: Very low
B13: Specificity | C13: Hansen | D13: QUADAS-2 | E13: 8 | F13: Low | G13: 5 | H13: 3 | I13: 0 | J13: =G13/E13 -> 0.625 | K13: N | L13: Upgrade | M13: NR | N13: Downgrade | O13: Low | Q13: Adults only | R13: Wrist only | S13: 0 | T13: Downgrade | U13: Very low
B14: Sensitivity | C14: Husarek | D14: QUADAS-2 | E14: 17 | F14: Low | G14: 6 | H14: 9 | I14: 2 | J14: =G14/E14 -> 0.35294118 | K14: Y | L14: Downgrade | M14: NR | N14: Downgrade | O14: Very low | Q14: Y | R14: Y | S14: 2 | T14: Upgrade | U14: Low
B15: Specificity | C15: Husarek | D15: QUADAS-2 | E15: 17 | F15: Low | G15: 6 | H15: 9 | I15: 2 | J15: =G15/E15 -> 0.35294118 | K15: Y | L15: Downgrade | M15: NR | N15: Downgrade | O15: Very low | Q15: Y | R15: Y | S15: 2 | T15: Upgrade | U15: Low
B16: Sensitivity | C16: Ju | D16: QUADAS-2 | E16: 11 | F16: Low | G16: 4 | H16: 0 | I16: 7 | J16: =G16/E16 -> 0.36363636 | K16: N | L16: Downgrade | M16: N | N16: No change | O16: Very low
B17: Specificity | C17: Ju | D17: QUADAS-2 | E17: 11 | F17: Low | G17: 4 | H17: 0 | I17: 7 | J17: =G17/E17 -> 0.36363636 | K17: N | L17: Downgrade | M17: N | N17: No change | O17: Very low
B18: Sensitivity | C18: Jung | D18: QUADAS-2 | E18: 57 | F18: Low | G18: 40 | H18: 9 | I18: 0 | J18: 0.70175439 | K18: Y | L18: Upgrade | M18: Y | N18: Downgrade | O18: Low | Q18: Y | R18: Y | S18: 2 | T18: Upgrade | U18: Moderate | W18: Y | X18: Y | Y18: 2 | Z18: Upgrade | AA18: Moderate | AI18: Y | AJ18: Y | AK18: 2 | AL18: Upgrade | AM18: Moderate | AO18: Y | AP18: Y | AQ18: 2 | AR18: Upgrade | AS18: Moderate
B19: Specificity | C19: Jung | D19: QUADAS-2 | E19: 57 | F19: Low | G19: 40 | H19: 9 | I19: 0 | J19: 0.70175439 | K19: Y | L19: Upgrade | M19: Y | N19: Downgrade | O19: Low | Q19: Y | R19: Y | S19: 2 | T19: Upgrade | U19: Moderate | W19: Y | X19: Y | Y19: 2 | Z19: Upgrade | AA19: Moderate | AI19: Y | AJ19: Y | AK19: 2 | AL19: Upgrade | AM19: Moderate | AO19: Y | AP19: Y | AQ19: 2 | AR19: Upgrade | AS19: Moderate
B20: Sensitivity | C20: Kraus | D20: QUADAS-2 | E20: 7 | F20: Low | G20: 1 | H20: 8 | I20: 1 | J20: =G20/E20 -> 0.14285714 | K20: N | L20: Downgrade | M20: NR | N20: Downgrade | O20: Very low | Q20: Y | R20: Scaphoid only | S20: 1 | T20: No change | U20: Very low
B21: Specificity | C21: Kraus | D21: QUADAS-2 | E21: 7 | F21: Low | G21: 1 | H21: 8 | I21: 1 | J21: =G21/E21 -> 0.14285714 | K21: N | L21: Downgrade | M21: NR | N21: Downgrade | O21: Very low | Q21: Y | R21: Scaphoid only | S21: 1 | T21: No change | U21: Very low
B22: Sensitivity | C22: Kuo | D22: PROBAST | E22: 32 | F22: Low | G22: 9 | H22: 1 | I22: 22 | J22: =G22/E22 -> 0.28125 | K22: N | L22: Downgrade | M22: NR | N22: No change | O22: Very low
B23: Specificity | C23: Kuo | D23: PROBAST | E23: 32 | F23: Low | G23: 9 | H23: 1 | I23: 22 | J23: =G23/E23 -> 0.28125 | K23: N | L23: Downgrade | M23: N | N23: No change | O23: Very low
B24: Sensitivity | C24: Li | D24: QUADAS-2 | E24: 81 | F24: Low | G24: 81 | H24: 0 | I24: 0 | J24: =G24/E24 -> 1 | K24: Y | L24: Upgrade | M24: N | N24: No change | O24: Moderate | Q24: Adults only | R24: Vertebral only | S24: 0 | T24: Downgrade | U24: Low | W24: Adults only | X24: Vertebral only | Y24: 0 | Z24: Downgrade | AA24: Low
B25: Specificity | C25: Li | D25: QUADAS-2 | E25: 81 | F25: Low | G25: 81 | H25: 0 | I25: 0 | J25: =G25/E25 -> 1 | K25: Y | L25: Upgrade | M25: N | N25: No change | O25: Moderate | Q25: Adults only | R25: Vertebral only | S25: 0 | T25: Downgrade | U25: Low | W25: Adults only | X25: Vertebral only | Y25: 0 | Z25: Downgrade | AA25: Low
B26: Sensitivity | C26: Lopez-Melia | D26: QUADAS-2 | E26: 7 | F26: Low | G26: 5 | H26: 1 | I26: 0 | J26: =G26/E26 -> 0.71428571 | K26: Y | L26: Upgrade | M26: NR | N26: Downgrade | O26: Low | W26: Y | X26: Rib only | Y26: 1 | Z26: No change | AA26: Low
B27: Specificity | C27: Lopez-Melia | E27: 7 | F27: Low
B28: Sensitivity | C28: Mellon | D28: QUADAS-2 | E28: 16 | F28: Low | G28: 8 | H28: 4 | I28: 4 | J28: =G28/E28 -> 0.5 | K28: N | L28: Downgrade | M28: NR | N28: Downgrade | O28: Very low | Q28: Y | R28: Upper limb only | S28: 1 | T28: No change | U28: Very low
B29: Specificity | C29: Mellon | D29: QUADAS-2 | E29: 16 | F29: Low | G29: 8 | H29: 4 | I29: 4 | J29: =G29/E29 -> 0.5 | K29: N | L29: Downgrade | M29: NR | N29: Downgrade | O29: Very low | Q29: Y | R29: Upper limb only | S29: 1 | T29: No change | U29: Very low
B30: Sensitivity | C30: Nowroozi | D30: QUADAS-2 | E30: 83 | F30: Low | G30: 3 | H30: Unclear | I30: Unclear | J30: =G30/E30 -> 0.036144578 | K30: N | L30: Downgrade | M30: N | N30: No change | O30: Very low | Q30: Y | R30: Y | S30: 2 | T30: Upgrade | U30: Low
B31: Specificity | C31: Nowroozi | D31: QUADAS-2 | E31: 83 | F31: Low | G31: 3 | H31: Unclear | I31: Unclear | J31: =G31/E31 -> 0.036144578 | K31: N | L31: Downgrade | M31: N | N31: No change | O31: Very low | Q31: Y | R31: Y | S31: 2 | T31: Upgrade | U31: Low
B32: Sensitivity | C32: Ramadanov | D32: QUADAS-2 | E32: 11 | F32: Low | G32: 4 | H32: 5 | I32: 2 | J32: =G32/E32 -> 0.36363636 | K32: Y | L32: Upgrade | M32: Y | N32: Downgrade | O32: Low | Q32: Y | R32: Femoral neck only | S32: 1 | T32: No change | U32: Low
B33: Specificity | C33: Ramadanov | D33: QUADAS-2 | E33: 11 | F33: Low | G33: 4 | H33: 5 | I33: 2 | J33: =G33/E33 -> 0.36363636 | K33: Y | L33: Upgrade | M33: Y | N33: Downgrade | O33: Low | Q33: Y | R33: Femoral neck only | S33: 1 | T33: No change | U33: Low
B34: Sensitivity | C34: Sharifi | D34: QUADAS-2 | E34: 11 | F34: Low | G34: 1 | H34: 4 | I34: 6 | J34: =G34/E34 -> 0.090909091 | K34: N | L34: Downgrade | M34: N | N34: No change | O34: Very low | W34: Y | X34: Skull only | Y34: 1 | Z34: No change | AA34: Very low
B35: Specificity | C35: Sharifi | D35: QUADAS-2 | E35: 11 | F35: Low | G35: 1 | H35: 4 | I35: 6 | J35: =G35/E35 -> 0.090909091 | K35: N | L35: Downgrade | M35: N | N35: No change | O35: Very low | W35: Y | X35: Skull only | Y35: 1 | Z35: No change | AA35: Very low
B36: Sensitivity | C36: Suen | D36: QUADAS-2 | E36: 20 | F36: Low | G36: 16 | H36: 4 | I36: 0 | J36: =G36/E36 -> 0.8 | K36: Y | L36: Upgrade | M36: NR | N36: Downgrade | O36: Low | Q36: Y | R36: Wrist only | S36: 1 | T36: No change | U36: Low
B37: Specificity | C37: Suen | D37: QUADAS-2 | E37: 20 | F37: Low | G37: 16 | H37: 4 | I37: 0 | J37: =G37/E37 -> 0.8 | K37: Y | L37: Upgrade | M37: NR | N37: Downgrade | O37: Low | Q37: Y | R37: Wrist only | S37: 1 | T37: No change | U37: Low
B38: Sensitivity | C38: Wong | D38: QUADAS-2 | E38: 32 | F38: Low | G38: 13 | H38: 15 | I38: 4 | J38: =G38/E38 -> 0.40625 | K38: N | L38: Downgrade | M38: Y | N38: Downgrade | O38: Very low | Q38: Y | R38: Hand and wrist only | S38: 1 | T38: No change | U38: Very low
B39: Specificity | C39: Wong | D39: QUADAS-2 | E39: 32 | F39: Low | G39: 13 | H39: 15 | I39: 4 | J39: =G39/E39 -> 0.40625 | K39: N | L39: Downgrade | M39: Y | N39: Downgrade | O39: Very low | Q39: Y | R39: Hand and wrist only | S39: 1 | T39: No change | U39: Very low
B40: Sensitivity | C40: van den Broek | D40: QUADAS-2 | E40: 12 | F40: Low | G40: 10 | H40: 2 | I40: 0 | J40: =G40/E40 -> 0.83333333 | K40: Y | L40: Upgrade | M40: Y | N40: Downgrade | O40: Low | W40: Y | X40: Rib only | Y40: 1 | Z40: No change | AA40: Low
...

Sheet GRADE by MA, fracture location
A1: Outcome | C1: Meta-analysis | D1: Source of risk of bias information | E1: Number of contributing primary studies | F1: Starting level | G1: Risk of bias | K1: Outcome | M1: Publication bias | N1: Outcome | O1: Interim GRADE | P1: Outcome | Q1: Indirectness | S1: Outcome | U1: Final GRADE | V1: Outcome | W1: Indirectness | Y1: Outcome | AA1: Final GRADE | AB1: Outcome | AC1: Indirectness | AE1: Outcome | AG1: Final GRADE | AH1: Outcome | AI1: Indirectness | AK1: Outcome | AM1: Final GRADE
G2: Low | H2: Moderate | I2: High | J2: % low risk | K2: Classification | L2: GRADE | M2: Yes/No/NR | N2: GRADE | Q2: Population | R2: Imaging | S2: How many points | T2: GRADE | W2: Population | X2: Imaging | Y2: How many points | Z2: GRADE | AC2: Population | AD2: Imaging | AE2: How many points | AF2: GRADE | AI2: Population | AJ2: Imaging | AK2: How many points | AL2: GRADE
B3: Finding
A4: Start here: | B4: Sensitivity | C4: Beculic | D4: QUADAS-2 | E4: 17 | F4: Low | G4: 8 | H4: 3 | I4: 0 | J4: =G4/E4 -> 0.47058824 | K4: Unclear | L4: Downgrade | M4: N | N4: No change | O4: Very low | P4: Axial | Q4: Y | R4: Y | S4: 2 | T4: Upgrade | U4: Low | V4: Lower limb | AB4: Upper limb | AH4: Skull
B5: Specificity | C5: Beculic | D5: QUADAS-2 | E5: 17 | F5: Low | G5: 8 | H5: 3 | I5: 0 | J5: =G5/E5 -> 0.47058824 | K5: Unclear | L5: Downgrade | M5: N | N5: No change | O5: Very low | Q5: Y | R5: Y | S5: 2 | T5: Upgrade | U5: Low
B6: Sensitivity | C6: Binh | D6: QUADAS-2 | E6: 6 | F6: Low | G6: 5 | H6: 1 | I6: 0 | J6: =G6/E6 -> 0.83333333 | K6: Y | L6: Upgrade | M6: N | N6: No change | O6: Moderate | AC6: N | AD6: Y | AE6: 1 | AF6: No change | AG6: Moderate
B7: Specificity | C7: Binh | D7: QUADAS-2 | E7: 6 | F7: Low | G7: 5 | H7: 1 | I7: 0 | J7: =G7/E7 -> 0.83333333 | K7: Y | L7: Upgrade | M7: N | N7: No change | O7: Moderate | AC7: N | AD7: Y | AE7: 1 | AF7: No change | AG7: Moderate
B8: Sensitivity | C8: Dashti | D8: QUADAS-2 | E8: 5 | F8: Low | G8: 1 | H8: 3 | I8: 1 | J8: =G8/E8 -> 0.2 | K8: N | L8: Downgrade | M8: N | N8: No change | O8: Very low | AI8: Y | AJ8: Radiographs only | AK8: 1 | AL8: No change | AM8: Very low
B9: Specificity | C9: Dashti | D9: QUADAS-2 | E9: 5 | F9: Low | G9: 1 | H9: 3 | I9: 1 | J9: =G9/E9 -> 0.2 | K9: N | L9: Downgrade | M9: N | N9: No change | O9: Very low | AI9: Y | AJ9: Radiographs only | AK9: 1 | AL9: No change | AM9: Very low
B10: Sensitivity | C10: Den Hengst | D10: MINORS | E10: 20 | F10: Low | G10: 4 | H10: NR | I10: NR | J10: 0.2 | K10: Y | L10: Upgrade | M10: NR | N10: Downgrade | O10: Low | Q10: Y | R10: CT only | S10: 1 | T10: No change | U10: Low
B11: Specificity | C11: Den Hengst | E11: 20
B12: Sensitivity | C12: Hansen | D12: QUADAS-2 | E12: 8 | F12: Low | G12: 5 | H12: 3 | I12: 0 | J12: =G12/E12 -> 0.625 | K12: N | L12: Upgrade | M12: NR | N12: Downgrade | O12: Low | AC12: Adults only | AD12: Radiographs only | AE12: 0 | AF12: Downgrade | AG12: Very low
B13: Specificity | C13: Hansen | D13: QUADAS-2 | E13: 8 | F13: Low | G13: 5 | H13: 3 | I13: 0 | J13: =G13/E13 -> 0.625 | K13: N | L13: Upgrade | M13: NR | N13: Downgrade | O13: Low | AC13: Adults only | AD13: Radiographs only | AE13: 0 | AF13: Downgrade | AG13: Very low
B14: Sensitivity | C14: Husarek | D14: QUADAS-2 | E14: 17 | F14: Low | G14: 6 | H14: 9 | I14: 2 | J14: =G14/E14 -> 0.35294118 | K14: Y | L14: Downgrade | M14: NR | N14: Downgrade | O14: Very low | Q14: Y | R14: Radiographs only | S14: 1 | T14: No change | U14: Very low | W14: Y | X14: Radiographs only | Y14: 1 | Z14: No change | AA14: Very low | AC14: Y | AD14: Radiographs only | AE14: 1 | AF14: No change | AG14: Very low
B15: Specificity | C15: Husarek | D15: QUADAS-2 | E15: 17 | F15: Low | G15: 6 | H15: 9 | I15: 2 | J15: =G15/E15 -> 0.35294118 | K15: Y | L15: Downgrade | M15: NR | N15: Downgrade | O15: Very low | Q15: Y | R15: Radiographs only | S15: 1 | T15: No change | U15: Very low | W15: Y | X15: Radiographs only | Y15: 1 | Z15: No change | AA15: Very low | AC15: Y | AD15: Radiographs only | AE15: 1 | AF15: No change | AG15: Very low
B16: Sensitivity | C16: Ju | D16: QUADAS-2 | E16: 11 | F16: Low | G16: 4 | H16: 0 | I16: 7 | J16: =G16/E16 -> 0.36363636 | K16: N | L16: Downgrade | M16: N | N16: No change | O16: Very low | AI16: Y | AJ16: Y | AK16: 2 | AL16: Upgrade | AM16: Low
B17: Specificity | C17: Ju | D17: QUADAS-2 | E17: 11 | F17: Low | G17: 4 | H17: 0 | I17: 7 | J17: =G17/E17 -> 0.36363636 | K17: N | L17: Downgrade | M17: N | N17: No change | O17: Very low | AI17: Y | AJ17: Y | AK17: 2 | AL17: Upgrade | AM17: Low
B18: Sensitivity | C18: Jung | D18: QUADAS-2 | E18: 57 | F18: Low | G18: 40 | H18: 9 | I18: 0 | J18: 0.70175439 | K18: Y | L18: Upgrade | M18: Y | N18: Downgrade | O18: Low | Q18: Y | R18: Y | S18: 2 | T18: Upgrade | U18: Moderate | W18: Y | X18: Y | Y18: 2 | Z18: Upgrade | AA18: Moderate | AC18: Y | AD18: Y | AE18: 2 | AF18: Upgrade | AG18: Moderate
B19: Specificity | C19: Jung | D19: QUADAS-2 | E19: 57 | F19: Low | G19: 40 | H19: 9 | I19: 0 | J19: 0.70175439 | K19: Y | L19: Upgrade | M19: Y | N19: Downgrade | O19: Low | Q19: Y | R19: Y | S19: 2 | T19: Upgrade | U19: Moderate | W19: Y | X19: Y | Y19: 2 | Z19: Upgrade | AA19: Moderate | AC19: Y | AD19: Y | AE19: 2 | AF19: Upgrade | AG19: Moderate
B20: Sensitivity | C20: Kraus | D20: QUADAS-2 | E20: 7 | F20: Low | G20: 1 | H20: 8 | I20: 1 | J20: =G20/E20 -> 0.14285714 | K20: N | L20: Downgrade | M20: NR | N20: Downgrade | O20: Very low | AC20: Y | AD20: Radiographs only | AE20: 1 | AF20: No change | AG20: Very low
B21: Specificity | C21: Kraus | D21: QUADAS-2 | E21: 7 | F21: Low | G21: 1 | H21: 8 | I21: 1 | J21: =G21/E21 -> 0.14285714 | K21: N | L21: Downgrade | M21: NR | N21: Downgrade | O21: Very low | AC21: Y | AD21: Radiographs only | AE21: 1 | AF21: No change | AG21: Very low
B22: Sensitivity | C22: Kuo | D22: PROBAST | E22: 32 | F22: Low | G22: 9 | H22: 1 | I22: 22 | J22: =G22/E22 -> 0.28125 | K22: N | L22: Downgrade | M22: NR | N22: No change | O22: Very low
B23: Specificity | C23: Kuo | D23: PROBAST | E23: 32 | F23: Low | G23: 9 | H23: 1 | I23: 22 | J23: =G23/E23 -> 0.28125 | K23: N | L23: Downgrade | M23: N | N23: No change | O23: Very low
B24: Sensitivity | C24: Li | D24: QUADAS-2 | E24: 81 | F24: Low | G24: 81 | H24: 0 | I24: 0 | J24: =G24/E24 -> 1 | K24: Y | L24: Upgrade | M24: N | N24: No change | O24: Moderate | Q24: Adults only | R24: Y | S24: 1 | T24: No change | U24: Moderate
B25: Specificity | C25: Li | D25: QUADAS-2 | E25: 81 | F25: Low | G25: 81 | H25: 0 | I25: 0 | J25: =G25/E25 -> 1 | K25: Y | L25: Upgrade | M25: N | N25: No change | O25: Moderate | Q25: Adults only | R25: Y | S25: 1 | T25: No change | U25: Moderate
B26: Sensitivity | C26: Lopez-Melia | D26: QUADAS-2 | E26: 7 | F26: Low | G26: 5 | H26: 1 | I26: 0 | J26: =G26/E26 -> 0.71428571 | K26: Y | L26: Upgrade | M26: NR | N26: Downgrade | O26: Low | Q26: Y | R26: CT only | S26: 1 | T26: No change | U26: Low
B27: Specificity | C27: Lopez-Melia | E27: 7 | F27: Low
B28: Sensitivity | C28: Mellon | D28: QUADAS-2 | E28: 16 | F28: Low | G28: 8 | H28: 4 | I28: 4 | J28: =G28/E28 -> 0.5 | K28: N | L28: Downgrade | M28: NR | N28: Downgrade | O28: Very low | AC28: Y | AD28: Radiographs only | AE28: 1 | AF28: No change | AG28: Very low
B29: Specificity | C29: Mellon | D29: QUADAS-2 | E29: 16 | F29: Low | G29: 8 | H29: 4 | I29: 4 | J29: =G29/E29 -> 0.5 | K29: N | L29: Downgrade | M29: NR | N29: Downgrade | O29: Very low | AC29: Y | AD29: Radiographs only | AE29: 1 | AF29: No change | AG29: Very low
B30: Sensitivity | C30: Nowroozi | D30: QUADAS-2 | E30: 83 | F30: Low | G30: 3 | H30: Unclear | I30: Unclear | J30: =G30/E30 -> 0.036144578 | K30: N | L30: Downgrade | M30: N | N30: No change | O30: Very low | Q30: Y | R30: Radiographs only | S30: 1 | T30: No change | U30: Very low | W30: Y | X30: Radiographs only | Y30: 1 | Z30: No change | AA30: Very low | AC30: Y | AD30: Radiographs only | AE30: 1 | AF30: No change | AG30: Very low
B31: Specificity | C31: Nowroozi | D31: QUADAS-2 | E31: 83 | F31: Low | G31: 3 | H31: Unclear | I31: Unclear | J31: =G31/E31 -> 0.036144578 | K31: N | L31: Downgrade | M31: N | N31: No change | O31: Very low | Q31: Y | R31: Radiographs only | S31: 1 | T31: No change | U31: Very low | W31: Y | X31: Radiographs only | Y31: 1 | Z31: No change | AA31: Very low | AC31: Y | AD31: Radiographs only | AE31: 1 | AF31: No change | AG31: Very low
B32: Sensitivity | C32: Ramadanov | D32: QUADAS-2 | E32: 11 | F32: Low | G32: 4 | H32: 5 | I32: 2 | J32: =G32/E32 -> 0.36363636 | K32: Y | L32: Upgrade | M32: Y | N32: Downgrade | O32: Low | W32: Y | X32: Radiographs only | Y32: 1 | Z32: No change | AA32: Low
B33: Specificity | C33: Ramadanov | D33: QUADAS-2 | E33: 11 | F33: Low | G33: 4 | H33: 5 | I33: 2 | J33: =G33/E33 -> 0.36363636 | K33: Y | L33: Upgrade | M33: Y | N33: Downgrade | O33: Low | W33: Y | X33: Radiographs only | Y33: 1 | Z33: No change | AA33: Low
B34: Sensitivity | C34: Sharifi | D34: QUADAS-2 | E34: 11 | F34: Low | G34: 1 | H34: 4 | I34: 6 | J34: =G34/E34 -> 0.090909091 | K34: N | L34: Downgrade | M34: N | N34: No change | O34: Very low | AI34: Y | AJ34: CT only | AK34: 1 | AL34: No change | AM34: Very low
B35: Specificity | C35: Sharifi | D35: QUADAS-2 | E35: 11 | F35: Low | G35: 1 | H35: 4 | I35: 6 | J35: =G35/E35 -> 0.090909091 | K35: N | L35: Downgrade | M35: N | N35: No change | O35: Very low | AI35: Y | AJ35: CT only | AK35: 1 | AL35: No change | AM35: Very low
B36: Sensitivity | C36: Suen | D36: QUADAS-2 | E36: 20 | F36: Low | G36: 16 | H36: 4 | I36: 0 | J36: =G36/E36 -> 0.8 | K36: Y | L36: Upgrade | M36: NR | N36: Downgrade | O36: Low | AC36: Y | AD36: Radiographs only | AE36: 1 | AF36: No change | AG36: Low
B37: Specificity | C37: Suen | D37: QUADAS-2 | E37: 20 | F37: Low | G37: 16 | H37: 4 | I37: 0 | J37: =G37/E37 -> 0.8 | K37: Y | L37: Upgrade | M37: NR | N37: Downgrade | O37: Low | AC37: Y | AD37: Radiographs only | AE37: 1 | AF37: No change | AG37: Low
B38: Sensitivity | C38: Wong | D38: QUADAS-2 | E38: 32 | F38: Low | G38: 13 | H38: 15 | I38: 4 | J38: =G38/E38 -> 0.40625 | K38: N | L38: Downgrade | M38: Y | N38: Downgrade | O38: Very low | AC38: Y | AD38: Y | AE38: 2 | AF38: Upgrade | AG38: Low
B39: Specificity | C39: Wong | D39: QUADAS-2 | E39: 32 | F39: Low | G39: 13 | H39: 15 | I39: 4 | J39: =G39/E39 -> 0.40625 | K39: N | L39: Downgrade | M39: Y | N39: Downgrade | O39: Very low | AC39: Y | AD39: Y | AE39: 2 | AF39: Upgrade | AG39: Low
B40: Sensitivity | C40: van den Broek | D40: QUADAS-2 | E40: 12 | F40: Low | G40: 10 | H40: 2 | I40: 0 | J40: =G40/E40 -> 0.83333333 | K40: Y | L40: Upgrade | M40: Y | N40: Downgrade | O40: Low | Q40: Y | R40: CT only | S40: 1 | T40: No change | U40: Low
...

Sheet GRADE by MA, population
A1: Outcome | C1: Meta-analysis | D1: Source of risk of bias information | E1: Number of contributing primary studies | F1: Starting level | G1: Risk of bias | K1: Outcome | M1: Publication bias | N1: Outcome | O1: Interim GRADE | P1: Outcome | Q1: Indirectness | T1: Outcome | V1: Final GRADE | W1: Outcome | X1: Indirectness | AA1: Outcome | AC1: Final GRADE
G2: Low | H2: Moderate | I2: High | J2: % low risk | K2: Classiciation | L2: GRADE | M2: Yes/No/NR | N2: GRADE | Q2: Population | R2: Imaging | S2: Fracture location | T2: How many points | U2: GRADE | X2: Population | Y2: Imaging | Z2: Fracture location | AA2: How many points | AB2: GRADE
B3: Finding
A4: Start here: | B4: Sensitivity | C4: Beculic | D4: QUADAS-2 | E4: 17 | F4: Low | G4: 8 | H4: 3 | I4: 0 | J4: 0.47059 | K4: Unclear | L4: Downgrade | M4: N | N4: No change | O4: Very low | P4: Paediatric | W4: Adult
B5: Specificity | C5: Beculic | D5: QUADAS-2 | E5: 17 | F5: Low | G5: 8 | H5: 3 | I5: 0 | J5: 0.47059 | K5: Unclear | L5: Downgrade | M5: N | N5: No change | O5: Very low
B6: Sensitivity | C6: Binh | D6: QUADAS-2 | E6: 6 | F6: Low | G6: 5 | H6: 1 | I6: 0 | J6: =G6/E6 -> 0.83333333 | K6: Y | L6: Upgrade | M6: N | N6: No change | O6: Moderate | Q6: Y | R6: Radiograph only | S6: Elbow only | T6: 1 | U6: Downgrade | V6: Low
B7: Specificity | C7: Binh | D7: QUADAS-2 | E7: 6 | F7: Low | G7: 5 | H7: 1 | I7: 0 | J7: =G7/E7 -> 0.83333333 | K7: Y | L7: Upgrade | M7: N | N7: No change | O7: Moderate | Q7: Y | R7: Radiograph only | S7: Elbow only | T7: 1 | U7: Downgrade | V7: Low
B8: Sensitivity | C8: Dashti | D8: QUADAS-2 | E8: 5 | F8: Low | G8: 1 | H8: 3 | I8: 1 | J8: =G8/E8 -> 0.2 | K8: N | L8: Downgrade | M8: N | N8: No change | O8: Very low
B9: Specificity | C9: Dashti | D9: QUADAS-2 | E9: 5 | F9: Low | G9: 1 | H9: 3 | I9: 1 | J9: =G9/E9 -> 0.2 | K9: N | L9: Downgrade | M9: N | N9: No change | O9: Very low
B10: Sensitivity | C10: Den Hengst | D10: MINORS | E10: 20 | F10: Low | G10: 4 | H10: NR | I10: NR | J10: 0.2 | K10: Y | L10: Upgrade | M10: NR | N10: Downgrade | O10: Low
B11: Specificity | C11: Den Hengst | E11: 20
B12: Sensitivity | C12: Hansen | D12: QUADAS-2 | E12: 8 | F12: Low | G12: 5 | H12: 3 | I12: 0 | J12: =G12/E12 -> 0.625 | K12: N | L12: Upgrade | M12: NR | N12: Downgrade | O12: Low | X12: Y | Y12: Radiographs only | Z12: Wrist only | AA12: 1 | AB12: Downgrade | AC12: Very low
B13: Specificity | C13: Hansen | D13: QUADAS-2 | E13: 8 | F13: Low | G13: 5 | H13: 3 | I13: 0 | J13: =G13/E13 -> 0.625 | K13: N | L13: Upgrade | M13: NR | N13: Downgrade | O13: Low | X13: Y | Y13: Radiographs only | Z13: Wrist only | AA13: 1 | AB13: Downgrade | AC13: Very low
B14: Sensitivity | C14: Husarek | D14: QUADAS-2 | E14: 17 | F14: Low | G14: 6 | H14: 9 | I14: 2 | J14: =G14/E14 -> 0.35294118 | K14: Y | L14: Downgrade | M14: NR | N14: Downgrade | O14: Very low
B15: Specificity | C15: Husarek | D15: QUADAS-2 | E15: 17 | F15: Low | G15: 6 | H15: 9 | I15: 2 | J15: =G15/E15 -> 0.35294118 | K15: Y | L15: Downgrade | M15: NR | N15: Downgrade | O15: Very low
B16: Sensitivity | C16: Ju | D16: QUADAS-2 | E16: 11 | F16: Low | G16: 4 | H16: 0 | I16: 7 | J16: =G16/E16 -> 0.36363636 | K16: N | L16: Downgrade | M16: N | N16: No change | O16: Very low
